<?xml version="1.0" encoding="utf-8"?>
<!-- This URDF was automatically created by SolidWorks to URDF Exporter! Originally created by Stephen Brawner (brawner@gmail.com) 
     Commit Version: 1.6.0-4-g7f85cfe  Build Version: 1.6.7995.38578
     For more information, please see http://wiki.ros.org/sw_urdf_exporter -->
<robot
  name="Assem1_urdf">
  <link
    name="base_link">
    <inertial>
      <origin
        xyz="0.285543629985341 0.194998849134254 0.401468537938472"
        rpy="0 0 0" />
      <mass
        value="0.444641789820814" />
      <inertia
        ixx="0.000422378679078014"
        ixy="1.64969033205762E-07"
        ixz="-3.42815948251253E-09"
        iyy="0.000422371403132014"
        iyz="-3.14388659635174E-09"
        izz="0.000783515664494764" />
    </inertial>
    <visual>
      <origin
        xyz="0 0 0"
        rpy="0 0 0" />
      <geometry>
        <mesh
          filename="package://Assem1_urdf/meshes/base_link.STL" />
      </geometry>
      <material
        name="">
        <color
          rgba="0.792156862745098 0.819607843137255 0.933333333333333 1" />
      </material>
    </visual>
    <collision>
      <origin
        xyz="0 0 0"
        rpy="0 0 0" />
      <geometry>
        <mesh
          filename="package://Assem1_urdf/meshes/base_link.STL" />
      </geometry>
    </collision>
  </link>
  <link
    name="cbracket">
    <inertial>
      <origin
        xyz="0.285539869458885 0.195012953101029 0.338647445445658"
        rpy="0 0 0" />
      <mass
        value="0.194139827709801" />
      <inertia
        ixx="0.000187909216337473"
        ixy="1.78676211485826E-09"
        ixz="-1.04515996229664E-08"
        iyy="0.000246157573305321"
        iyz="3.72184232658196E-08"
        izz="0.000261155018400835" />
    </inertial>
    <visual>
      <origin
        xyz="0 0 0"
        rpy="0 0 0" />
      <geometry>
        <mesh
          filename="package://Assem1_urdf/meshes/cbracket.STL" />
      </geometry>
      <material
        name="">
        <color
          rgba="0.792156862745098 0.819607843137255 0.933333333333333 1" />
      </material>
    </visual>
    <collision>
      <origin
        xyz="0 0 0"
        rpy="0 0 0" />
      <geometry>
        <mesh
          filename="package://Assem1_urdf/meshes/cbracket.STL" />
      </geometry>
    </collision>
  </link>
  <joint
    name="j1"
    type="revolute">
    <origin
      xyz="0 0 0"
      rpy="0 0 0" />
    <parent
      link="base_link" />
    <child
      link="cbracket" />
    <axis
      xyz="0 0 -1" />
    <limit
      lower="0"
      upper="3.142"
      effort="300"
      velocity="3" />
  </joint>
  <link
    name="acc1">
    <inertial>
      <origin
        xyz="0.285548873939453 0.172594740542959 0.276531202836462"
        rpy="0 0 0" />
      <mass
        value="0.580805573043362" />
      <inertia
        ixx="0.000492159787240385"
        ixy="1.50936769975587E-09"
        ixz="-8.56532320526593E-08"
        iyy="0.000905329045450532"
        iyz="-4.37109713281588E-09"
        izz="0.000492444403465044" />
    </inertial>
    <visual>
      <origin
        xyz="0 0 0"
        rpy="0 0 0" />
      <geometry>
        <mesh
          filename="package://Assem1_urdf/meshes/acc1.STL" />
      </geometry>
      <material
        name="">
        <color
          rgba="0.792156862745098 0.819607843137255 0.933333333333333 1" />
      </material>
    </visual>
    <collision>
      <origin
        xyz="0 0 0"
        rpy="0 0 0" />
      <geometry>
        <mesh
          filename="package://Assem1_urdf/meshes/acc1.STL" />
      </geometry>
    </collision>
  </link>
  <joint
    name="j2"
    type="revolute">
    <origin
      xyz="0 0 0"
      rpy="0 0 0" />
    <parent
      link="cbracket" />
    <child
      link="acc1" />
    <axis
      xyz="0 -1 0" />
    <limit
      lower="0"
      upper="3.142"
      effort="300"
      velocity="3" />
  </joint>
  <link
    name="acc2">
    <inertial>
      <origin
        xyz="0.285544075192303 0.0624141292517647 0.276530056499566"
        rpy="0 0 0" />
      <mass
        value="0.487854306232371" />
      <inertia
        ixx="0.000462080596257296"
        ixy="-4.52868915355638E-09"
        ixz="-8.61850755093484E-08"
        iyy="0.000789118999661582"
        iyz="1.04646866712411E-09"
        izz="0.000461798296135276" />
    </inertial>
    <visual>
      <origin
        xyz="0 0 0"
        rpy="0 0 0" />
      <geometry>
        <mesh
          filename="package://Assem1_urdf/meshes/acc2.STL" />
      </geometry>
      <material
        name="">
        <color
          rgba="0.792156862745098 0.819607843137255 0.933333333333333 1" />
      </material>
    </visual>
    <collision>
      <origin
        xyz="0 0 0"
        rpy="0 0 0" />
      <geometry>
        <mesh
          filename="package://Assem1_urdf/meshes/acc2.STL" />
      </geometry>
    </collision>
  </link>
  <joint
    name="j3"
    type="revolute">
    <origin
      xyz="0 0 0"
      rpy="0 0 0" />
    <parent
      link="acc1" />
    <child
      link="acc2" />
    <axis
      xyz="0 -1 0" />
    <limit
      lower="0"
      upper="3.142"
      effort="300"
      velocity="3" />
  </joint>
  <link
    name="leg1">
    <inertial>
      <origin
        xyz="0.148710766849133 0.0259864476273492 0.278510543162463"
        rpy="0 0 0" />
      <mass
        value="0.36589545292241" />
      <inertia
        ixx="0.000466959962116375"
        ixy="3.62148513981734E-07"
        ixz="7.41602205024745E-05"
        iyy="0.00547244468330663"
        iyz="-1.39736383693459E-07"
        izz="0.00501424101543542" />
    </inertial>
    <visual>
      <origin
        xyz="0 0 0"
        rpy="0 0 0" />
      <geometry>
        <mesh
          filename="package://Assem1_urdf/meshes/leg1.STL" />
      </geometry>
      <material
        name="">
        <color
          rgba="0.792156862745098 0.819607843137255 0.933333333333333 1" />
      </material>
    </visual>
    <collision>
      <origin
        xyz="0 0 0"
        rpy="0 0 0" />
      <geometry>
        <mesh
          filename="package://Assem1_urdf/meshes/leg1.STL" />
      </geometry>
    </collision>
  </link>
  <joint
    name="j4"
    type="revolute">
    <origin
      xyz="0 0 0"
      rpy="0 0 0" />
    <parent
      link="acc2" />
    <child
      link="leg1" />
    <axis
      xyz="0 -1 0" />
    <limit
      lower="3.142"
      upper="-3.142"
      effort="200"
      velocity="3" />
  </joint>
  <link
    name="lowleg1">
    <inertial>
      <origin
        xyz="0.00943634547376737 0.00638662686843915 0.169284361125698"
        rpy="0 0 0" />
      <mass
        value="0.662807706648712" />
      <inertia
        ixx="0.00531282955170692"
        ixy="-1.02126813768498E-05"
        ixz="-0.000269149166010491"
        iyy="0.00576046743541068"
        iyz="-0.000183354822039283"
        izz="0.00049846188856484" />
    </inertial>
    <visual>
      <origin
        xyz="0 0 0"
        rpy="0 0 0" />
      <geometry>
        <mesh
          filename="package://Assem1_urdf/meshes/lowleg1.STL" />
      </geometry>
      <material
        name="">
        <color
          rgba="0.792156862745098 0.819607843137255 0.933333333333333 1" />
      </material>
    </visual>
    <collision>
      <origin
        xyz="0 0 0"
        rpy="0 0 0" />
      <geometry>
        <mesh
          filename="package://Assem1_urdf/meshes/lowleg1.STL" />
      </geometry>
    </collision>
  </link>
  <joint
    name="j7"
    type="revolute">
    <origin
      xyz="0 0 0"
      rpy="0 0 0" />
    <parent
      link="leg1" />
    <child
      link="lowleg1" />
    <axis
      xyz="0 1 0" />
    <limit
      lower="0"
      upper="3.142"
      effort="200"
      velocity="3" />
  </joint>
  <link
    name="leg2">
    <inertial>
      <origin
        xyz="0.148710766849134 -0.0140135523726508 0.278510543162465"
        rpy="0 0 0" />
      <mass
        value="0.365895452922409" />
      <inertia
        ixx="0.000466959962116351"
        ixy="3.62148513983982E-07"
        ixz="7.41602205024681E-05"
        iyy="0.005472444683306"
        iyz="-1.39736383693121E-07"
        izz="0.00501424101543481" />
    </inertial>
    <visual>
      <origin
        xyz="0 0 0"
        rpy="0 0 0" />
      <geometry>
        <mesh
          filename="package://Assem1_urdf/meshes/leg2.STL" />
      </geometry>
      <material
        name="">
        <color
          rgba="0.792156862745098 0.819607843137255 0.933333333333333 1" />
      </material>
    </visual>
    <collision>
      <origin
        xyz="0 0 0"
        rpy="0 0 0" />
      <geometry>
        <mesh
          filename="package://Assem1_urdf/meshes/leg2.STL" />
      </geometry>
    </collision>
  </link>
  <joint
    name="j5"
    type="revolute">
    <origin
      xyz="0 0 0"
      rpy="0 0 0" />
    <parent
      link="acc2" />
    <child
      link="leg2" />
    <axis
      xyz="0 -1 0" />
    <limit
      lower="3.142"
      upper="-3.142"
      effort="200"
      velocity="3" />
  </joint>
  <link
    name="lowleg2">
    <inertial>
      <origin
        xyz="0.00943634547376737 0.00638662686843915 0.169284361125698"
        rpy="0 0 0" />
      <mass
        value="0.662807706648712" />
      <inertia
        ixx="0.00531282955170692"
        ixy="-1.02126813768498E-05"
        ixz="-0.000269149166010491"
        iyy="0.00576046743541068"
        iyz="-0.000183354822039283"
        izz="0.00049846188856484" />
    </inertial>
    <visual>
      <origin
        xyz="0 0 0"
        rpy="0 0 0" />
      <geometry>
        <mesh
          filename="package://Assem1_urdf/meshes/lowleg2.STL" />
      </geometry>
      <material
        name="">
        <color
          rgba="0.792156862745098 0.819607843137255 0.933333333333333 1" />
      </material>
    </visual>
    <collision>
      <origin
        xyz="0 0 0"
        rpy="0 0 0" />
      <geometry>
        <mesh
          filename="package://Assem1_urdf/meshes/lowleg2.STL" />
      </geometry>
    </collision>
  </link>
  <joint
    name="j8"
    type="revolute">
    <origin
      xyz="0 0 0"
      rpy="0 0 0" />
    <parent
      link="leg2" />
    <child
      link="lowleg2" />
    <axis
      xyz="0 1 0" />
    <limit
      lower="0"
      upper="3.142"
      effort="200"
      velocity="3" />
  </joint>
  <link
    name="pulley">
    <inertial>
      <origin
        xyz="0.28556949252123 0.00600097666043496 0.276527680420605"
        rpy="0 0 0" />
      <mass
        value="0.15148726652934" />
      <inertia
        ixx="9.46097837970229E-05"
        ixy="3.96555051164422E-09"
        ixz="3.59496822912099E-08"
        iyy="0.000169400649471206"
        iyz="1.87163807693523E-09"
        izz="9.46089948969572E-05" />
    </inertial>
    <visual>
      <origin
        xyz="0 0 0"
        rpy="0 0 0" />
      <geometry>
        <mesh
          filename="package://Assem1_urdf/meshes/pulley.STL" />
      </geometry>
      <material
        name="">
        <color
          rgba="0.792156862745098 0.819607843137255 0.933333333333333 1" />
      </material>
    </visual>
    <collision>
      <origin
        xyz="0 0 0"
        rpy="0 0 0" />
      <geometry>
        <mesh
          filename="package://Assem1_urdf/meshes/pulley.STL" />
      </geometry>
    </collision>
  </link>
  <joint
    name="j6"
    type="revolute">
    <origin
      xyz="0 0 0"
      rpy="0 0 0" />
    <parent
      link="acc2" />
    <child
      link="pulley" />
    <axis
      xyz="0 -1 0" />
    <limit
      lower="0"
      upper="3.142"
      effort="300"
      velocity="3" />
  </joint>
</robot>