<?xml version="1.0" encoding="utf-8"?>
<!-- This URDF was automatically created by SolidWorks to URDF Exporter! Originally created by Stephen Brawner (brawner@gmail.com) 
     Commit Version: 1.6.0-4-g7f85cfe  Build Version: 1.6.7995.38578
     For more information, please see http://wiki.ros.org/sw_urdf_exporter -->
<robot
  name="design1_urdf">
  <link
    name="base_link">
    <inertial>
      <origin
        xyz="2.90327133735477E-06 -1.15086574470347E-06 0.0490628648498654"
        rpy="0 0 0" />
      <mass
        value="0.444641789820814" />
      <inertia
        ixx="0.000422378679078014"
        ixy="-1.6496903320577E-07"
        ixz="-3.42815948251568E-09"
        iyy="0.000422371403132014"
        iyz="3.14388659634852E-09"
        izz="0.000783515664494764" />
    </inertial>
    <visual>
      <origin
        xyz="0 0 0"
        rpy="0 0 0" />
      <geometry>
        <mesh
          filename="/home/ananya/ros2_ws/src/my_box_bot_gazebo/meshes
/base_link.STL" />
      </geometry>
      <material
        name="">
        <color
          rgba="0.792156862745098 0.819607843137255 0.933333333333333 1" />
      </material>
    </visual>
    <collision>
      <origin
        xyz="0 0 0"
        rpy="0 0 0" />
      <geometry>
        <mesh
          filename="/home/ananya/ros2_ws/src/my_box_bot_gazebo/meshes
/base_link.STL" />
      </geometry>
    </collision>
  </link>
  <link
    name="cbracket">
    <inertial>
      <origin
        xyz="6.66379779351058E-06 1.29531010308603E-05 0.11188395734268"
        rpy="0 0 0" />
      <mass
        value="0.194139827709801" />
      <inertia
        ixx="0.000187909216337473"
        ixy="-1.7867621148589E-09"
        ixz="-1.04515996229646E-08"
        iyy="0.00024615757330532"
        iyz="-3.72184232657869E-08"
        izz="0.000261155018400835" />
    </inertial>
    <visual>
      <origin
        xyz="0 0 0"
        rpy="0 0 0" />
      <geometry>
        <mesh
          filename="/home/ananya/ros2_ws/src/my_box_bot_gazebo/meshes
/cbracket.STL" />
      </geometry>
      <material
        name="">
        <color
          rgba="0.792156862745098 0.819607843137255 0.933333333333333 1" />
      </material>
    </visual>
    <collision>
      <origin
        xyz="0 0 0"
        rpy="0 0 0" />
      <geometry>
        <mesh
          filename="/home/ananya/ros2_ws/src/my_box_bot_gazebo/meshes
/cbracket.STL" />
      </geometry>
    </collision>
  </link>
  <joint
    name="j1"
    type="revolute">
    <origin
      xyz="0 0 0"
      rpy="0 0 0" />
    <parent
      link="base_link" />
    <child
      link="cbracket" />
    <axis
      xyz="0 0 1" />
    <limit
      lower="0"
      upper="3.142"
      effort="300"
      velocity="3" />
  </joint>
  <link
    name="acc1">
    <inertial>
      <origin
        xyz="-2.34068277550539E-06 -0.0224052594570396 0.174000199951876"
        rpy="0 0 0" />
      <mass
        value="0.580805573043355" />
      <inertia
        ixx="0.000492159787240379"
        ixy="-1.50936770006795E-09"
        ixz="-8.56532320557236E-08"
        iyy="0.000905329045450525"
        iyz="4.37109713345542E-09"
        izz="0.000492444403465043" />
    </inertial>
    <visual>
      <origin
        xyz="0 0 0"
        rpy="0 0 0" />
      <geometry>
        <mesh
          filename="/home/ananya/ros2_ws/src/my_box_bot_gazebo/meshes
/acc1.STL" />
      </geometry>
      <material
        name="">
        <color
          rgba="0.792156862745098 0.819607843137255 0.933333333333333 1" />
      </material>
    </visual>
    <collision>
      <origin
        xyz="0 0 0"
        rpy="0 0 0" />
      <geometry>
        <mesh
          filename="/home/ananya/ros2_ws/src/my_box_bot_gazebo/meshes
/acc1.STL" />
      </geometry>
    </collision>
  </link>
  <joint
    name="j2"
    type="revolute">
    <origin
      xyz="0 0 0"
      rpy="0 0 0" />
    <parent
      link="cbracket" />
    <child
      link="acc1" />
    <axis
      xyz="0 -1 0" />
    <limit
      lower="0"
      upper="3.142"
      effort="300"
      velocity="3" />
  </joint>
  <link
    name="acc2">
    <inertial>
      <origin
        xyz="2.4580643749085E-06 -0.132585870748234 0.174001346288772"
        rpy="0 0 0" />
      <mass
        value="0.487854306232371" />
      <inertia
        ixx="0.000462080596257296"
        ixy="4.52868915355271E-09"
        ixz="-8.61850755093217E-08"
        iyy="0.000789118999661582"
        iyz="-1.04646866712111E-09"
        izz="0.000461798296135276" />
    </inertial>
    <visual>
      <origin
        xyz="0 0 0"
        rpy="0 0 0" />
      <geometry>
        <mesh
          filename="/home/ananya/ros2_ws/src/my_box_bot_gazebo/meshes
/acc2.STL" />
      </geometry>
      <material
        name="">
        <color
          rgba="0.792156862745098 0.819607843137255 0.933333333333333 1" />
      </material>
    </visual>
    <collision>
      <origin
        xyz="0 0 0"
        rpy="0 0 0" />
      <geometry>
        <mesh
          filename="/home/ananya/ros2_ws/src/my_box_bot_gazebo/meshes
/acc2.STL" />
      </geometry>
    </collision>
  </link>
  <joint
    name="j3"
    type="revolute">
    <origin
      xyz="0 0 0"
      rpy="0 0 0" />
    <parent
      link="acc1" />
    <child
      link="acc2" />
    <axis
      xyz="0 -1 0" />
    <limit
      lower="0"
      upper="3.142"
      effort="300"
      velocity="3" />
  </joint>
  <link
    name="leg1">
    <inertial>
      <origin
        xyz="0.136835766407545 -0.169013552372649 0.172020859625875"
        rpy="0 0 0" />
      <mass
        value="0.36589545292241" />
      <inertia
        ixx="0.000466959962116375"
        ixy="-3.62148513981743E-07"
        ixz="7.41602205024747E-05"
        iyy="0.00547244468330666"
        iyz="1.39736383693459E-07"
        izz="0.00501424101543545" />
    </inertial>
    <visual>
      <origin
        xyz="0 0 0"
        rpy="0 0 0" />
      <geometry>
        <mesh
          filename="/home/ananya/ros2_ws/src/my_box_bot_gazebo/meshes
/leg1.STL" />
      </geometry>
      <material
        name="">
        <color
          rgba="0.792156862745098 0.819607843137255 0.933333333333333 1" />
      </material>
    </visual>
    <collision>
      <origin
        xyz="0 0 0"
        rpy="0 0 0" />
      <geometry>
        <mesh
          filename="/home/ananya/ros2_ws/src/my_box_bot_gazebo/meshes
/leg1.STL" />
      </geometry>
    </collision>
  </link>
  <joint
    name="j4"
    type="revolute">
    <origin
      xyz="0 0 0"
      rpy="0 0 0" />
    <parent
      link="acc2" />
    <child
      link="leg1" />
    <axis
      xyz="0 -1 0" />
    <limit
      lower="3.142"
      upper="-3.142"
      effort="200"
      velocity="3" />
  </joint>
  <link
    name="lowleg1">
    <inertial>
      <origin
        xyz="0.276110187782911 -0.188613373131559 0.28124704166264"
        rpy="0 0 0" />
      <mass
        value="0.662807706648712" />
      <inertia
        ixx="0.00531282955170692"
        ixy="1.02126813768498E-05"
        ixz="-0.000269149166010491"
        iyy="0.00576046743541068"
        iyz="0.000183354822039283"
        izz="0.00049846188856484" />
    </inertial>
    <visual>
      <origin
        xyz="0 0 0"
        rpy="0 0 0" />
      <geometry>
        <mesh
          filename="/home/ananya/ros2_ws/src/my_box_bot_gazebo/meshes
/lowleg1.STL" />
      </geometry>
      <material
        name="">
        <color
          rgba="0.792156862745098 0.819607843137255 0.933333333333333 1" />
      </material>
    </visual>
    <collision>
      <origin
        xyz="0 0 0"
        rpy="0 0 0" />
      <geometry>
        <mesh
          filename="/home/ananya/ros2_ws/src/my_box_bot_gazebo/meshes
/lowleg1.STL" />
      </geometry>
    </collision>
  </link>
  <joint
    name="j7"
    type="revolute">
    <origin
      xyz="0 0 0"
      rpy="0 0 0" />
    <parent
      link="leg1" />
    <child
      link="lowleg1" />
    <axis
      xyz="0 1 0" />
    <limit
      lower="0"
      upper="3.142"
      effort="200"
      velocity="3" />
  </joint>
  <link
    name="leg2">
    <inertial>
      <origin
        xyz="0.136835766407544 -0.209013552372649 0.172020859625873"
        rpy="0 0 0" />
      <mass
        value="0.365895452922409" />
      <inertia
        ixx="0.000466959962116351"
        ixy="-3.62148513983994E-07"
        ixz="7.41602205024679E-05"
        iyy="0.00547244468330599"
        iyz="1.3973638369312E-07"
        izz="0.00501424101543479" />
    </inertial>
    <visual>
      <origin
        xyz="0 0 0"
        rpy="0 0 0" />
      <geometry>
        <mesh
          filename="/home/ananya/ros2_ws/src/my_box_bot_gazebo/meshes
/leg2.STL" />
      </geometry>
      <material
        name="">
        <color
          rgba="0.792156862745098 0.819607843137255 0.933333333333333 1" />
      </material>
    </visual>
    <collision>
      <origin
        xyz="0 0 0"
        rpy="0 0 0" />
      <geometry>
        <mesh
          filename="/home/ananya/ros2_ws/src/my_box_bot_gazebo/meshes
/leg2.STL" />
      </geometry>
    </collision>
  </link>
  <joint
    name="j5"
    type="revolute">
    <origin
      xyz="0 0 0"
      rpy="0 0 0" />
    <parent
      link="acc2" />
    <child
      link="leg2" />
    <axis
      xyz="0 -1 0" />
    <limit
      lower="3.142"
      upper="-3.142"
      effort="200"
      velocity="3" />
  </joint>
  <link
    name="lowleg2">
    <inertial>
      <origin
        xyz="0.276110187782911 -0.188613373131559 0.28124704166264"
        rpy="0 0 0" />
      <mass
        value="0.662807706648712" />
      <inertia
        ixx="0.00531282955170692"
        ixy="1.02126813768498E-05"
        ixz="-0.000269149166010491"
        iyy="0.00576046743541068"
        iyz="0.000183354822039283"
        izz="0.00049846188856484" />
    </inertial>
    <visual>
      <origin
        xyz="0 0 0"
        rpy="0 0 0" />
      <geometry>
        <mesh
          filename="/home/ananya/ros2_ws/src/my_box_bot_gazebo/meshes
/lowleg2.STL" />
      </geometry>
      <material
        name="">
        <color
          rgba="0.792156862745098 0.819607843137255 0.933333333333333 1" />
      </material>
    </visual>
    <collision>
      <origin
        xyz="0 0 0"
        rpy="0 0 0" />
      <geometry>
        <mesh
          filename="/home/ananya/ros2_ws/src/my_box_bot_gazebo/meshes
/lowleg2.STL" />
      </geometry>
    </collision>
  </link>
  <joint
    name="j8"
    type="revolute">
    <origin
      xyz="0 0 0"
      rpy="0 0 0" />
    <parent
      link="leg2" />
    <child
      link="lowleg2" />
    <axis
      xyz="0 1 0" />
    <limit
      lower="0"
      upper="3.142"
      effort="200"
      velocity="3" />
  </joint>
  <link
    name="pulley">
    <inertial>
      <origin
        xyz="-2.29592645520256E-05 -0.188999023339563 0.174003722367733"
        rpy="0 0 0" />
      <mass
        value="0.15148726652934" />
      <inertia
        ixx="9.46097837970229E-05"
        ixy="-3.96555051164265E-09"
        ixz="3.59496822912E-08"
        iyy="0.000169400649471206"
        iyz="-1.87163807693509E-09"
        izz="9.46089948969573E-05" />
    </inertial>
    <visual>
      <origin
        xyz="0 0 0"
        rpy="0 0 0" />
      <geometry>
        <mesh
          filename="/home/ananya/ros2_ws/src/my_box_bot_gazebo/meshes
/pulley.STL" />
      </geometry>
      <material
        name="">
        <color
          rgba="0.792156862745098 0.819607843137255 0.933333333333333 1" />
      </material>
    </visual>
    <collision>
      <origin
        xyz="0 0 0"
        rpy="0 0 0" />
      <geometry>
        <mesh
          filename="/home/ananya/ros2_ws/src/my_box_bot_gazebo/meshes
/pulley.STL" />
      </geometry>
    </collision>
  </link>
  <joint
    name="j6"
    type="revolute">
    <origin
      xyz="0 0 0"
      rpy="0 0 0" />
    <parent
      link="acc2" />
    <child
      link="pulley" />
    <axis
      xyz="0 -1 0" />
    <limit
      lower="0"
      upper="3.142"
      effort="300"
      velocity="3" />
  </joint>
</robot>
